<?xml version="1.0" ?>
<!-- =================================================================================== -->
<!-- |    This document was autogenerated by xacro from aloha.urdf.xacro               | -->
<!-- |    EDITING THIS FILE BY HAND IS NOT RECOMMENDED                                 | -->
<!-- =================================================================================== -->
<xacro:robot name="aloha">
  <link name="left/base_link">
    <inertial>
      <origin rpy="0 0 0" xyz="0 0 0"/>
      <mass value="0.969034"/>
      <inertia ixx="0.0071633" ixy="0.0" ixz="0.0" iyy="0.00602451" iyz="0.0" izz="0.00169819"/>
    </inertial>
    <visual>
      <geometry>
        <mesh filename="meshes/vx300s_1_base.stl" scale="0.001 0.001 0.001"/>
      </geometry>
      <material name="black">
        <color rgba="0.15 0.15 0.15 1"/>
      </material>
    </visual>
    <collision>
      <geometry>
        <mesh filename="meshes/vx300s_1_base.stl" scale="0.001 0.001 0.001"/>
      </geometry>
    </collision>
  </link>
  <link name="left/shoulder_link">
    <inertial>
      <origin rpy="0 0 0" xyz="0 0 0"/>
      <mass value="0.798614"/>
      <inertia ixx="0.00120156" ixy="0.0" ixz="0.0" iyy="0.00113744" iyz="0.0" izz="0.0009388"/>
    </inertial>
    <visual>
      <geometry>
        <mesh filename="meshes/vx300s_2_shoulder.stl" scale="0.001 0.001 0.001"/>
      </geometry>
      <material name="black">
        <color rgba="0.15 0.15 0.15 1"/>
      </material>
    </visual>
    <collision>
      <geometry>
        <mesh filename="meshes/vx300s_2_shoulder.stl" scale="0.001 0.001 0.001"/>
      </geometry>
    </collision>
  </link>
  <joint name="left/waist" type="revolute">
    <origin rpy="0 0 0" xyz="0 0 0.079"/>
    <parent link="left/base_link"/>
    <child link="left/shoulder_link"/>
    <axis xyz="0 0 1"/>
    <limit effort="35" lower="-3.14158" upper="3.14158" velocity="1.0"/>
    <dynamics damping="5.76"/>
  </joint>
  <link name="right/base_link">
    <inertial>
      <origin rpy="0 0 0" xyz="0 0 0"/>
      <mass value="0.969034"/>
      <inertia ixx="0.0071633" ixy="0.0" ixz="0.0" iyy="0.00602451" iyz="0.0" izz="0.00169819"/>
    </inertial>
    <visual>
      <geometry>
        <mesh filename="meshes/vx300s_1_base.stl" scale="0.001 0.001 0.001"/>
      </geometry>
      <material name="black">
        <color rgba="0.15 0.15 0.15 1"/>
      </material>
    </visual>
    <collision>
      <geometry>
        <mesh filename="meshes/vx300s_1_base.stl" scale="0.001 0.001 0.001"/>
      </geometry>
    </collision>
  </link>
  <link name="right/shoulder_link">
    <inertial>
      <origin rpy="0 0 0" xyz="0 0 0"/>
      <mass value="0.798614"/>
      <inertia ixx="0.00120156" ixy="0.0" ixz="0.0" iyy="0.00113744" iyz="0.0" izz="0.0009388"/>
    </inertial>
    <visual>
      <geometry>
        <mesh filename="meshes/vx300s_2_shoulder.stl" scale="0.001 0.001 0.001"/>
      </geometry>
      <material name="black">
        <color rgba="0.15 0.15 0.15 1"/>
      </material>
    </visual>
    <collision>
      <geometry>
        <mesh filename="meshes/vx300s_2_shoulder.stl" scale="0.001 0.001 0.001"/>
      </geometry>
    </collision>
  </link>
  <joint name="right/waist" type="revolute">
    <origin rpy="0 0 0" xyz="0 0 0.079"/>
    <parent link="right/base_link"/>
    <child link="right/shoulder_link"/>
    <axis xyz="0 0 1"/>
    <limit effort="35" lower="-3.14158" upper="3.14158" velocity="1.0"/>
    <dynamics damping="5.76"/>
  </joint>
  <!-- Finger Coupling -->
  <joint name="left/finger_coupling" type="fixed">
    <parent link="left/left_finger_link"/>
    <child link="left/right_finger_link"/>
  </joint>
  <joint name="right/finger_coupling" type="fixed">
    <parent link="right/left_finger_link"/>
    <child link="right/right_finger_link"/>
  </joint>
</xacro:robot>
